<mujoco>
<option timestep="0.01"/>
<worldbody>
    <!-- The manipulator agent body -->
    <body pos="0 0 0" name="agent">
        <!-- TODO: Replace with cylinder when MJX supports -->
        <geom type="sphere" size="{agent_radius}" pos="0 0 {agent_radius}" mass="0.1" rgba="0.1 0.1 0.9 1"/>
        <joint type="slide" axis="1 0 0" damping="0.1" stiffness="0" name="agent_x"/>
        <joint type="slide" axis="0 1 0" damping="0.1" stiffness="0" name="agent_y"/>
    </body>
    <body pos="0 0 0" name="block">
        <!-- The horizontal box -->
        <geom type="box" size="{double_block_scale:.4} {half_block_scale:.4} 0.5" 
            pos="0 -{half_block_scale:.4} 0.5" mass="0.03" rgba="0.467 0.533 0.6 1"/>
        <!-- The vertical box -->
        <geom type="box" size="{half_block_scale:.4} {one_and_half_block_scale:.4} 0.5"
            pos="0 -{two_and_half_block_scale} 0.5" mass="0.03" rgba="0.467 0.533 0.6 1"/>

        <joint type="slide" axis="1 0 0" damping="5" stiffness="0"/>
        <joint type="slide" axis="0 1 0" damping="5" stiffness="0"/>
        <!-- Hinge through block COM -->
        <joint type="hinge" axis="0 0 1" damping="0.3" stiffness="0" pos="0 -{com_offset:.4} 0"/>
    </body>
    <!-- The boundary planes -->
    <geom pos="-{half_world_scale} 0 0" size="{world_scale} {world_scale} 0.1"  xyaxes="0 1 0 0 0 1" type="plane"/>
    <geom pos="{half_world_scale} 0 0" size="{world_scale} {world_scale} 0.1"   xyaxes="0 0 1 0 1 0" type="plane"/>
    <geom pos="0 -{half_world_scale} 0" size="{world_scale} {world_scale} 0.1"  xyaxes="0 0 1 1 0 0" type="plane"/>
    <geom pos="0 {half_world_scale} 0" size="{world_scale} {world_scale} 0.1"   xyaxes="1 0 0 0 0 1" type="plane"/>
</worldbody>
<actuator>
    <motor ctrllimited="true" ctrlrange="-10.0 10.0" gear="1.0" joint="agent_x"/>
    <motor ctrllimited="true" ctrlrange="-10.0 10.0" gear="1.0" joint="agent_y"/>
</actuator>
</mujoco>
